<?xml version="1.0" encoding="UTF-8"?>
<!-- Generated by org.testng.reporters.JUnitReportReporter -->
<testsuite hostname="P231WFA061142" failures="0" tests="3" name="com.framework.DynamicTest2" time="28.768" errors="1" timestamp="2022-10-10T13:26:18 ICT" skipped="0">
  <testcase classname="com.framework.DynamicTest2" name="TestLogin2" time="4.835"/>
  <system-out/>
  <testcase classname="com.framework.DynamicTest2" name="TestLogin2" time="14.384">
    <error message="Error on &lt;br/&gt;Keyword : assertWebElementExist&lt;br/&gt;Object Name : spanAlertFailedLogin&lt;br/&gt;Value : assert failed login&lt;br/&gt;Description  Xpath : null" type="java.lang.NullPointerException">
        <![CDATA[java.lang.NullPointerException: Error on <br/>Keyword : assertWebElementExist<br/>Object Name : spanAlertFailedLogin<br/>Value : assert failed login<br/>Description  Xpath : null
at com.framework.baseFunctions.BaseController.dynamicMethod(BaseController.java:76)
at com.framework.baseFunctions.BaseController.<init>(BaseController.java:36)
at com.framework.DynamicTest2.execute(DynamicTest2.java:69)
at com.framework.DynamicTest2.TestLogin2(DynamicTest2.java:45)
at java.base/jdk.internal.reflect.NativeMethodAccessorImpl.invoke0(Native Method)
at java.base/jdk.internal.reflect.NativeMethodAccessorImpl.invoke(NativeMethodAccessorImpl.java:62)
at java.base/jdk.internal.reflect.DelegatingMethodAccessorImpl.invoke(DelegatingMethodAccessorImpl.java:43)
at java.base/java.lang.reflect.Method.invoke(Method.java:566)
at org.testng.internal.invokers.MethodInvocationHelper.invokeMethod(MethodInvocationHelper.java:139)
at org.testng.internal.invokers.TestInvoker.invokeMethod(TestInvoker.java:677)
at org.testng.internal.invokers.TestInvoker.invokeTestMethod(TestInvoker.java:221)
at org.testng.internal.invokers.TestMethodWithDataProviderMethodWorker.call(TestMethodWithDataProviderMethodWorker.java:80)
at org.testng.internal.invokers.TestMethodWithDataProviderMethodWorker.call(TestMethodWithDataProviderMethodWorker.java:17)
at java.base/java.util.concurrent.FutureTask.run$$$capture(FutureTask.java:264)
at java.base/java.util.concurrent.FutureTask.run(FutureTask.java)
at java.base/java.util.concurrent.Executors$RunnableAdapter.call(Executors.java:515)
at java.base/java.util.concurrent.FutureTask.run$$$capture(FutureTask.java:264)
at java.base/java.util.concurrent.FutureTask.run(FutureTask.java)
at java.base/java.util.concurrent.ThreadPoolExecutor.runWorker(ThreadPoolExecutor.java:1128)
at java.base/java.util.concurrent.ThreadPoolExecutor$Worker.run(ThreadPoolExecutor.java:628)
at java.base/java.lang.Thread.run(Thread.java:834)
]]>
    </error>
  </testcase> <!-- TestLogin2 -->
  <system-out/>
  <testcase classname="com.framework.DynamicTest2" name="TestLogin2" time="9.549"/>
  <system-out/>
</testsuite> <!-- com.framework.DynamicTest2 -->
